Workbook
Name 주기표: 참조!$A$2:$B$11
Name 목록_분류: 참조!$D$2:$D$7
Name 목록_난이도: 참조!$E$2:$E$4
Name 목록_자동화: 참조!$F$2:$F$4
Name 목록_우선순위: 참조!$G$2:$G$4
Name 목록_팀원: 참조!$H$2:$H$6
Name 목록_주기: 참조!$I$2:$I$11

Sheet 📖 사용안내
B2: 팀 R&R · 업무량 · 긴급배분 관리 시트
B3: 기획/PM/운영 팀용 · 주당 가용 32시간 기준 · 회당시간×주기 자동 월환산
B5: 이 파일의 구성
B6: 📑 ① 업무마스터(R&R) : 모든 업무를 한 줄씩 기록하는 핵심 시트 (샘플 20개 포함). 누가 주담당/백업인지, 얼마나 걸리는지, 누가 꼭 해야 하는지 정리.
B7: 📊 ② 팀원별 부하 : 위 데이터를 사람별로 자동 합산 — 누가 과부하이고 누가 여유 있는지 한눈에.
B8: 🚨 ③ 긴급배분 가이드 : 갑작스런 업무가 생겼을 때 '누가 받을 수 있는지'를 예상 소요시간 입력만으로 확인.
B9: 📝 빈 템플릿 : 샘플을 지운 깨끗한 양식. 우리 팀 실제 내용으로 채우면 됩니다.
B11: 작성 순서 (3단계)
B12: 1단계 '빈 템플릿' 또는 '① 업무마스터'에 팀의 모든 업무를 한 줄씩 적습니다. (먼저 떠오르는 대로, 빠짐없이)
B13: 2단계 각 업무의 '회당 소요시간'과 '주기'를 입력 → '월 환산 시간'이 자동 계산됩니다. '수시' 업무는 '월 발생횟수(직접)'에 한 달 평균 횟수 입력.
B14: 3단계 '주담당/백업담당/대체난이도/자동화/우선순위'를 드롭다운에서 선택. → ②·③ 시트는 자동으로 채워집니다.
B16: 각 항목의 의미
... B28: 문의·수정 필요 시 언제든 말씀해 주세요. 컬럼 추가/삭제, 부서별 분리, 구글시트 변환 모두 가능합니다.

Sheet ① 업무마스터(R&R)
A1: ① 업무 마스터 · R&R 정의표 (샘플 데이터)
A2: 입력 가이드 | ① 회당 소요시간 + 주기만 넣으면 '월 환산 시간'이 자동 계산됩니다. ② '수시' 업무는 '월 발생횟수(직접)' 칸에 한 달 평균 횟수를 직접 입력하세요. ③ 주담당/백업담당/분류 등은 셀 클릭 시 드롭다운에서 선택.
A3: No | B3: 업무명 | C3: 업무분류 | D3: 업무 설명 | E3: 주담당 | F3: 백업담당 | G3: 주기 | H3: 회당 소요시간(h) | I3: 월 발생횟수 (직접·수시용) | J3: 월 환산 시간(h) | K3: 필요 역량/스킬 | L3: 대체 난이도 | M3: 자동화 가능성 | N3: 우선 순위 | O3: 비고
A4: =IF($B4="","",ROW()-3) | B4: 주간 팀 회의 준비·진행 | C4: 운영 | D4: 아젠다 취합, 회의록 작성·공유 | E4: 김지원(팀장/PM) | F4: 이서연(서비스기획) | G4: 주간(주1회) | H4: 1.5 | J4: =IF($B4="","",$H4*IF($I4<>"",$I4,IFERROR(VLOOKUP($G4,주기표,2,FALSE),0))) | K4: 퍼실리테이션, 문서화 | L4: 낮음(누구나 가능) | M4: 일부 가능 | N4: 중 | O4: 회의록 템플릿화로 단축 여지
A5: =IF($B5="","",ROW()-3) | B5: 월간 사업보고서 작성 | C5: 기획 | D5: 실적·지표 종합, 경영진 보고자료 작성 | E5: 김지원(팀장/PM) | F5: 최유나(데이터/지표) | G5: 월간 | H5: 6 | J5: =IF($B5="","",$H5*IF($I5<>"",$I5,IFERROR(VLOOKUP($G5,주기표,2,FALSE),0))) | K5: 데이터 해석, 스토리텔링 | L5: 높음(전담 필수) | M5: 일부 가능 | N5: 상 | O5: 지표는 최유나 협조
A6: =IF($B6="","",ROW()-3) | B6: 분기 OKR 수립·리뷰 | C6: 기획 | D6: 목표 설정, 핵심지표 정의, 회고 | E6: 김지원(팀장/PM) | F6: 이서연(서비스기획) | G6: 분기 | H6: 8 | J6: =IF($B6="","",$H6*IF($I6<>"",$I6,IFERROR(VLOOKUP($G6,주기표,2,FALSE),0))) | K6: 전략기획 | L6: 높음(전담 필수) | M6: 불가 | N6: 상
A7: =IF($B7="","",ROW()-3) | B7: 유관부서 협업 미팅 | C7: 유관협업 | D7: 개발·디자인·마케팅 정례 싱크 | E7: 김지원(팀장/PM) | F7: 박민준(운영매니저) | G7: 주간(주1회) | H7: 2 | J7: =IF($B7="","",$H7*IF($I7<>"",$I7,IFERROR(VLOOKUP($G7,주기표,2,FALSE),0))) | K7: 커뮤니케이션, 조율 | L7: 중간(인수인계 필요) | M7: 불가 | N7: 중
A8: =IF($B8="","",ROW()-3) | B8: 서비스 기능 기획서 작성 | C8: 기획 | D8: 요구사항 정의, 기획서·스펙 문서화 | E8: 이서연(서비스기획) | F8: 김지원(팀장/PM) | G8: 격주 | H8: 8 | J8: =IF($B8="","",$H8*IF($I8<>"",$I8,IFERROR(VLOOKUP($G8,주기표,2,FALSE),0))) | K8: 서비스기획, UX | L8: 높음(전담 필수) | M8: 불가 | N8: 상
A9: =IF($B9="","",ROW()-3) | B9: 사용자 피드백 정리·분석 | C9: 기획 | D9: VOC·설문 취합, 인사이트 도출 | E9: 이서연(서비스기획) | F9: 박민준(운영매니저) | G9: 주간(주1회) | H9: 3 | J9: =IF($B9="","",$H9*IF($I9<>"",$I9,IFERROR(VLOOKUP($G9,주기표,2,FALSE),0))) | K9: 리서치, 정성분석 | L9: 중간(인수인계 필요) | M9: 일부 가능 | N9: 중
A10: =IF($B10="","",ROW()-3) | B10: 화면 정책·플로우 정의 | C10: 기획 | D10: 정책 정의, 화면 플로우/예외처리 정리 | E10: 이서연(서비스기획) | F10: 정현우(QA/지원) | G10: 격주 | H10: 5 | J10: =IF($B10="","",$H10*IF($I10<>"",$I10,IFERROR(VLOOKUP($G10,주기표,2,FALSE),0))) | K10: 기획, 논리설계 | L10: 높음(전담 필수) | M10: 불가 | N10: 중
A11: =IF($B11="","",ROW()-3) | B11: 릴리즈 노트 작성 | C11: 운영 | D11: 배포 내역 정리, 사내 공지 | E11: 이서연(서비스기획) | F11: 정현우(QA/지원) | G11: 월간 | H11: 2 | J11: =IF($B11="","",$H11*IF($I11<>"",$I11,IFERROR(VLOOKUP($G11,주기표,2,FALSE),0))) | K11: 문서화 | L11: 낮음(누구나 가능) | M11: 가능 | N11: 하 | O11: 자동화 1순위 후보
A12: =IF($B12="","",ROW()-3) | B12: 일일 운영 모니터링 | C12: 운영 | D12: 대시보드·알람 점검, 이상징후 확인 | E12: 박민준(운영매니저) | F12: 최유나(데이터/지표) | G12: 매일 | H12: 0.5 | J12: =IF($B12="","",$H12*IF($I12<>"",$I12,IFERROR(VLOOKUP($G12,주기표,2,FALSE),0))) | K12: 운영, 모니터링 | L12: 중간(인수인계 필요) | M12: 일부 가능 | N12: 상
A13: =IF($B13="","",ROW()-3) | B13: CS 이슈 대응·에스컬레이션 | C13: 운영 | D13: 문의 분류, 처리·유관부서 전달 | E13: 박민준(운영매니저) | F13: 정현우(QA/지원) | G13: 매일 | H13: 1 | J13: =IF($B13="","",$H13*IF($I13<>"",$I13,IFERROR(VLOOKUP($G13,주기표,2,FALSE),0))) | K13: CS, 문제해결 | L13: 중간(인수인계 필요) | M13: 불가 | N13: 상 | O13: 피크시 변동 큼
A14: =IF($B14="","",ROW()-3) | B14: 운영 프로세스 문서 업데이트 | C14: 관리/지원 | D14: 매뉴얼·플레이북 현행화 | E14: 박민준(운영매니저) | F14: 이서연(서비스기획) | G14: 월간 | H14: 3 | J14: =IF($B14="","",$H14*IF($I14<>"",$I14,IFERROR(VLOOKUP($G14,주기표,2,FALSE),0))) | K14: 문서화, 프로세스설계 | L14: 낮음(누구나 가능) | M14: 불가 | N14: 하
A15: =IF($B15="","",ROW()-3) | B15: 외부 벤더 커뮤니케이션 | C15: 유관협업 | D15: 제휴사·외주 일정·이슈 조율 | E15: 박민준(운영매니저) | F15: 김지원(팀장/PM) | G15: 주간(주1회) | H15: 1.5 | J15: =IF($B15="","",$H15*IF($I15<>"",$I15,IFERROR(VLOOKUP($G15,주기표,2,FALSE),0))) | K15: 협상, 커뮤니케이션 | L15: 중간(인수인계 필요) | M15: 불가 | N15: 중
A16: =IF($B16="","",ROW()-3) | B16: 주간 지표 대시보드 업데이트 | C16: 데이터/지표 | D16: 핵심지표 집계·갱신, 코멘트 | E16: 최유나(데이터/지표) | F16: 박민준(운영매니저) | G16: 주간(주1회) | H16: 2 | J16: =IF($B16="","",$H16*IF($I16<>"",$I16,IFERROR(VLOOKUP($G16,주기표,2,FALSE),0))) | K16: SQL, 데이터시각화 | L16: 중간(인수인계 필요) | M16: 가능 | N16: 중 | O16: 쿼리 자동화 가능
A17: =IF($B17="","",ROW()-3) | B17: 월간 성과 데이터 분석 리포트 | C17: 데이터/지표 | D17: 성과 심층분석, 개선 제언 | E17: 최유나(데이터/지표) | F17: 김지원(팀장/PM) | G17: 월간 | H17: 8 | J17: =IF($B17="","",$H17*IF($I17<>"",$I17,IFERROR(VLOOKUP($G17,주기표,2,FALSE),0))) | K17: 데이터분석, 통계 | L17: 높음(전담 필수) | M17: 일부 가능 | N17: 상
A18: =IF($B18="","",ROW()-3) | B18: A/B 테스트 설계·분석 | C18: 데이터/지표 | D18: 실험 설계, 결과 해석·의사결정 지원 | E18: 최유나(데이터/지표) | F18: 이서연(서비스기획) | G18: 격주 | H18: 5 | J18: =IF($B18="","",$H18*IF($I18<>"",$I18,IFERROR(VLOOKUP($G18,주기표,2,FALSE),0))) | K18: 실험설계, 통계 | L18: 높음(전담 필수) | M18: 불가 | N18: 중
A19: =IF($B19="","",ROW()-3) | B19: 데이터 추출 Ad-hoc 요청 대응 | C19: 데이터/지표 | D19: 비정기 데이터 추출·가공 요청 처리 | E19: 최유나(데이터/지표) | F19: 박민준(운영매니저) | G19: 수시 | H19: 1 | I19: 6 | J19: =IF($B19="","",$H19*IF($I19<>"",$I19,IFERROR(VLOOKUP($G19,주기표,2,FALSE),0))) | K19: SQL | L19: 중간(인수인계 필요) | M19: 일부 가능 | N19: 중 | O19: 월 평균 6건 가정(직접입력 예시)
A20: =IF($B20="","",ROW()-3) | B20: QA 테스트 케이스 작성 | C20: QA/품질 | D20: 기능별 테스트 시나리오 설계 | E20: 정현우(QA/지원) | F20: 이서연(서비스기획) | G20: 격주 | H20: 4 | J20: =IF($B20="","",$H20*IF($I20<>"",$I20,IFERROR(VLOOKUP($G20,주기표,2,FALSE),0))) | K20: QA, 테스트설계 | L20: 중간(인수인계 필요) | M20: 일부 가능 | N20: 중
A21: =IF($B21="","",ROW()-3) | B21: 배포 전 QA 검증 | C21: QA/품질 | D21: 릴리즈 전 회귀·시나리오 검증 | E21: 정현우(QA/지원) | F21: 박민준(운영매니저) | G21: 격주 | H21: 3 | J21: =IF($B21="","",$H21*IF($I21<>"",$I21,IFERROR(VLOOKUP($G21,주기표,2,FALSE),0))) | K21: QA, 꼼꼼함 | L21: 중간(인수인계 필요) | M21: 일부 가능 | N21: 상 | O21: 배포 주기 연동
A22: =IF($B22="","",ROW()-3) | B22: 버그 트래킹·리포팅 | C22: QA/품질 | D22: 이슈 등록·우선순위화, 처리현황 공유 | E22: 정현우(QA/지원) | F22: 박민준(운영매니저) | G22: 주간(주1회) | H22: 2 | J22: =IF($B22="","",$H22*IF($I22<>"",$I22,IFERROR(VLOOKUP($G22,주기표,2,FALSE),0))) | K22: 이슈관리 | L22: 낮음(누구나 가능) | M22: 일부 가능 | N22: 중
A23: =IF($B23="","",ROW()-3) | B23: 내부 위키·문서 정리 | C23: 관리/지원 | D23: 팀 지식베이스 구조화·정리 | E23: 정현우(QA/지원) | F23: 이서연(서비스기획) | G23: 월간 | H23: 3 | J23: =IF($B23="","",$H23*IF($I23<>"",$I23,IFERROR(VLOOKUP($G23,주기표,2,FALSE),0))) | K23: 문서화, 정리 | L23: 낮음(누구나 가능) | M23: 불가 | N23: 하
A24: =IF($B24="","",ROW()-3) | B24: 경영진 주간 실적 보고 | C24: 기획 | D24: 주요 지표·이슈 요약 보고 | E24: 김지원(팀장/PM) | F24: 최유나(데이터/지표) | G24: 주간(주1회) | H24: 2 | J24: =IF($B24="","",$H24*IF($I24<>"",$I24,IFERROR(VLOOKUP($G24,주기표,2,FALSE),0))) | K24: 요약, 보고 | L24: 중간(인수인계 필요) | M24: 일부 가능 | N24: 상
A25: =IF($B25="","",ROW()-3) | B25: 채용·면접 진행 | C25: 관리/지원 | D25: 서류검토·면접·피드백 | E25: 김지원(팀장/PM) | F25: 이서연(서비스기획) | G25: 수시 | H25: 2 | I25: 3 | J25: =IF($B25="","",$H25*IF($I25<>"",$I25,IFERROR(VLOOKUP($G25,주기표,2,FALSE),0))) | K25: 평가, 커뮤니케이션 | L25: 중간(인수인계 필요) | M25: 불가 | N25: 중 | O25: 채용시즌 변동 큼
A26: =IF($B26="","",ROW()-3) | B26: 디자인 QA·리뷰 | C26: 기획 | D26: 산출물 디자인 검수·피드백 | E26: 이서연(서비스기획) | F26: 정현우(QA/지원) | G26: 주간(주1회) | H26: 2 | J26: =IF($B26="","",$H26*IF($I26<>"",$I26,IFERROR(VLOOKUP($G26,주기표,2,FALSE),0))) | K26: UX, 디테일 | L26: 중간(인수인계 필요) | M26: 불가 | N26: 중
A27: =IF($B27="","",ROW()-3) | B27: 스프린트 백로그 관리 | C27: 기획 | D27: 이슈 정리·우선순위화·그루밍 | E27: 이서연(서비스기획) | F27: 김지원(팀장/PM) | G27: 주간(주1회) | H27: 1.5 | J27: =IF($B27="","",$H27*IF($I27<>"",$I27,IFERROR(VLOOKUP($G27,주기표,2,FALSE),0))) | K27: 기획, 일정관리 | L27: 중간(인수인계 필요) | M27: 일부 가능 | N27: 중
A28: =IF($B28="","",ROW()-3) | B28: 경쟁사·시장 리서치 | C28: 기획 | D28: 동향 모니터링·벤치마킹 정리 | E28: 이서연(서비스기획) | F28: 최유나(데이터/지표) | G28: 월간 | H28: 4 | J28: =IF($B28="","",$H28*IF($I28<>"",$I28,IFERROR(VLOOKUP($G28,주기표,2,FALSE),0))) | K28: 리서치 | L28: 낮음(누구나 가능) | M28: 불가 | N28: 하
A29: =IF($B29="","",ROW()-3) | B29: 주간 운영 현황 리포트 | C29: 데이터/지표 | D29: 운영 지표 집계·공유 | E29: 박민준(운영매니저) | F29: 최유나(데이터/지표) | G29: 주간(주1회) | H29: 2 | J29: =IF($B29="","",$H29*IF($I29<>"",$I29,IFERROR(VLOOKUP($G29,주기표,2,FALSE),0))) | K29: 데이터 정리 | L29: 중간(인수인계 필요) | M29: 가능 | N29: 중 | O29: 자동화 후보
A30: =IF($B30="","",ROW()-3) | B30: 정산·매출 데이터 점검 | C30: 운영 | D30: 정산 데이터 검증·이상 확인 | E30: 박민준(운영매니저) | F30: 최유나(데이터/지표) | G30: 주간(주1회) | H30: 1.5 | J30: =IF($B30="","",$H30*IF($I30<>"",$I30,IFERROR(VLOOKUP($G30,주기표,2,FALSE),0))) | K30: 꼼꼼함, 숫자감각 | L30: 중간(인수인계 필요) | M30: 일부 가능 | N30: 상
A31: =IF($B31="","",ROW()-3) | B31: 신규 입점·온보딩 처리 | C31: 운영 | D31: 신규 건 검수·등록·안내 | E31: 박민준(운영매니저) | F31: 정현우(QA/지원) | G31: 수시 | H31: 0.75 | I31: 8 | J31: =IF($B31="","",$H31*IF($I31<>"",$I31,IFERROR(VLOOKUP($G31,주기표,2,FALSE),0))) | K31: 운영, 꼼꼼함 | L31: 낮음(누구나 가능) | M31: 일부 가능 | N31: 중
A32: =IF($B32="","",ROW()-3) | B32: 장애·인시던트 대응 | C32: 운영 | D32: 긴급 이슈 처리·사후 리포트 | E32: 박민준(운영매니저) | F32: 정현우(QA/지원) | G32: 수시 | H32: 2 | I32: 4 | J32: =IF($B32="","",$H32*IF($I32<>"",$I32,IFERROR(VLOOKUP($G32,주기표,2,FALSE),0))) | K32: 문제해결, 침착함 | L32: 높음(전담 필수) | M32: 불가 | N32: 상 | O32: 발생 예측 어려움
A33: =IF($B33="","",ROW()-3) | B33: 일일 정산 마감 확인 | C33: 운영 | D33: 마감 배치·수치 확인 | E33: 박민준(운영매니저) | F33: 최유나(데이터/지표) | G33: 매일 | H33: 0.5 | J33: =IF($B33="","",$H33*IF($I33<>"",$I33,IFERROR(VLOOKUP($G33,주기표,2,FALSE),0))) | K33: 운영 | L33: 중간(인수인계 필요) | M33: 가능 | N33: 상 | O33: 자동화 후보
A34: =IF($B34="","",ROW()-3) | B34: 고객 문의 2차 대응 | C34: 운영 | D34: 에스컬레이션 건 심층 처리 | E34: 박민준(운영매니저) | F34: 정현우(QA/지원) | G34: 매일 | H34: 0.5 | J34: =IF($B34="","",$H34*IF($I34<>"",$I34,IFERROR(VLOOKUP($G34,주기표,2,FALSE),0))) | K34: CS, 문제해결 | L34: 중간(인수인계 필요) | M34: 불가 | N34: 중
A35: =IF($B35="","",ROW()-3) | B35: 주간 운영 회의 주재 | C35: 운영 | D35: 운영 이슈 점검 회의 진행 | E35: 박민준(운영매니저) | F35: 김지원(팀장/PM) | G35: 주간(주1회) | H35: 1.5 | J35: =IF($B35="","",$H35*IF($I35<>"",$I35,IFERROR(VLOOKUP($G35,주기표,2,FALSE),0))) | K35: 퍼실리테이션 | L35: 낮음(누구나 가능) | M35: 불가 | N35: 중
A36: =IF($B36="","",ROW()-3) | B36: 데이터 거버넌스·지표 정의 | C36: 데이터/지표 | D36: 지표 표준·정의 관리 | E36: 최유나(데이터/지표) | F36: 이서연(서비스기획) | G36: 월간 | H36: 4 | J36: =IF($B36="","",$H36*IF($I36<>"",$I36,IFERROR(VLOOKUP($G36,주기표,2,FALSE),0))) | K36: 데이터 모델링 | L36: 높음(전담 필수) | M36: 불가 | N36: 중
A37: =IF($B37="","",ROW()-3) | B37: 정기 코호트 분석 | C37: 데이터/지표 | D37: 리텐션·코호트 추이 분석 | E37: 최유나(데이터/지표) | F37: 김지원(팀장/PM) | G37: 격주 | H37: 4 | J37: =IF($B37="","",$H37*IF($I37<>"",$I37,IFERROR(VLOOKUP($G37,주기표,2,FALSE),0))) | K37: 데이터분석 | L37: 높음(전담 필수) | M37: 일부 가능 | N37: 중
A38: =IF($B38="","",ROW()-3) | B38: 일일 스모크 테스트 | C38: QA/품질 | D38: 핵심 플로우 일일 점검 | E38: 정현우(QA/지원) | F38: 박민준(운영매니저) | G38: 매일 | H38: 0.5 | J38: =IF($B38="","",$H38*IF($I38<>"",$I38,IFERROR(VLOOKUP($G38,주기표,2,FALSE),0))) | K38: QA | L38: 낮음(누구나 가능) | M38: 가능 | N38: 중 | O38: 자동화 후보
A39: =IF($B39="","",ROW()-3) | B39: QA 자동화 스크립트 유지보수 | C39: QA/품질 | D39: 테스트 자동화 코드 관리 | E39: 정현우(QA/지원) | F39: 최유나(데이터/지표) | G39: 주간(주1회) | H39: 2 | J39: =IF($B39="","",$H39*IF($I39<>"",$I39,IFERROR(VLOOKUP($G39,주기표,2,FALSE),0))) | K39: 테스트 자동화, 코드 | L39: 높음(전담 필수) | M39: 일부 가능 | N39: 중
A40: =IF($B40="","",ROW()-3) | J40: =IF($B40="","",$H40*IF($I40<>"",$I40,IFERROR(VLOOKUP($G40,주기표,2,FALSE),0)))
...

Sheet ② 팀원별 부하
A1: ② 팀원별 업무 부하 대시보드 (자동 계산)
A2: 기준: 주당 가용 32시간(회의·휴식 제외 실작업) × 4.33주 = 월 가용시간. 투입시간은 ① 업무마스터의 '주담당' 기준으로 자동 합산됩니다. 부하율 70%↑ 과부하 / 40~70% 적정 / 40%↓ 여유. (정기 업무 기준 — 나머지는 회의·돌발업무 몫)
A3: 팀원 | B3: 직무/역할 | C3: 주당 가용(h) | D3: 월 가용 (h) | E3: 월 투입(h) (주담당) | F3: 담당 업무수 | G3: 부하율 | H3: 여력(h) (월) | I3: 상태 | J3: 백업 지정수
A4: 김지원(팀장/PM) | B4: 팀장 / PM | C4: 32 | D4: =C4*4.33 | E4: =SUMIF('① 업무마스터(R&R)'!$E$4:$E$45,$A4,'① 업무마스터(R&R)'!$J$4:$J$45) | F4: =COUNTIF('① 업무마스터(R&R)'!$E$4:$E$45,$A4) | G4: =IFERROR(E4/D4,0) | H4: =D4-E4 | I4: =IF(G4>=0.7,"⚠ 과부하",IF(G4>=0.4,"적정","🟢 여유")) | J4: =COUNTIF('① 업무마스터(R&R)'!$F$4:$F$45,$A4)
A5: 이서연(서비스기획) | B5: 서비스 기획 | C5: 32 | D5: =C5*4.33 | E5: =SUMIF('① 업무마스터(R&R)'!$E$4:$E$45,$A5,'① 업무마스터(R&R)'!$J$4:$J$45) | F5: =COUNTIF('① 업무마스터(R&R)'!$E$4:$E$45,$A5) | G5: =IFERROR(E5/D5,0) | H5: =D5-E5 | I5: =IF(G5>=0.7,"⚠ 과부하",IF(G5>=0.4,"적정","🟢 여유")) | J5: =COUNTIF('① 업무마스터(R&R)'!$F$4:$F$45,$A5)
A6: 박민준(운영매니저) | B6: 운영 매니저 | C6: 32 | D6: =C6*4.33 | E6: =SUMIF('① 업무마스터(R&R)'!$E$4:$E$45,$A6,'① 업무마스터(R&R)'!$J$4:$J$45) | F6: =COUNTIF('① 업무마스터(R&R)'!$E$4:$E$45,$A6) | G6: =IFERROR(E6/D6,0) | H6: =D6-E6 | I6: =IF(G6>=0.7,"⚠ 과부하",IF(G6>=0.4,"적정","🟢 여유")) | J6: =COUNTIF('① 업무마스터(R&R)'!$F$4:$F$45,$A6)
A7: 최유나(데이터/지표) | B7: 데이터 / 지표 | C7: 32 | D7: =C7*4.33 | E7: =SUMIF('① 업무마스터(R&R)'!$E$4:$E$45,$A7,'① 업무마스터(R&R)'!$J$4:$J$45) | F7: =COUNTIF('① 업무마스터(R&R)'!$E$4:$E$45,$A7) | G7: =IFERROR(E7/D7,0) | H7: =D7-E7 | I7: =IF(G7>=0.7,"⚠ 과부하",IF(G7>=0.4,"적정","🟢 여유")) | J7: =COUNTIF('① 업무마스터(R&R)'!$F$4:$F$45,$A7)
A8: 정현우(QA/지원) | B8: QA / 지원 | C8: 32 | D8: =C8*4.33 | E8: =SUMIF('① 업무마스터(R&R)'!$E$4:$E$45,$A8,'① 업무마스터(R&R)'!$J$4:$J$45) | F8: =COUNTIF('① 업무마스터(R&R)'!$E$4:$E$45,$A8) | G8: =IFERROR(E8/D8,0) | H8: =D8-E8 | I8: =IF(G8>=0.7,"⚠ 과부하",IF(G8>=0.4,"적정","🟢 여유")) | J8: =COUNTIF('① 업무마스터(R&R)'!$F$4:$F$45,$A8)
A9: 팀 합계 / 평균 | D9: =SUM(D4:D8) | E9: =SUM(E4:E8) | F9: =SUM(F4:F8) | G9: =IFERROR(E9/D9,0) | H9: =SUM(H4:H8)

Sheet ③ 긴급배분 가이드
A1: ③ 긴급 업무 배분 가이드
A2: 갑작스런 업무 발생 시 ① 필요 역량이 맞는 사람을 먼저 추리고 → ② 아래 표에서 '여력(h)'이 큰 사람에게 배정하세요. B3 셀에 예상 소요시간(월,h)을 입력하면 누가 수용 가능한지 자동 표시됩니다.
A3: ▶ 긴급업무 예상 소요시간 (월, h): | B3: 45 | C3: ← 노란 칸에 입력
A5: 팀원 | B5: 현재 부하율 | C5: 여력(h,월) | D5: 상태 | E5: 수용 가능? | F5: 여유 후 부하율 | G5: 비고
A6: ='② 팀원별 부하'!A4 | B6: ='② 팀원별 부하'!G4 | C6: ='② 팀원별 부하'!H4 | D6: ='② 팀원별 부하'!I4 | E6: =IF(C6>=$B$3,"✅ 가능","❌ 어려움") | F6: =IFERROR(('② 팀원별 부하'!E4+$B$3)/'② 팀원별 부하'!D4,0)
A7: ='② 팀원별 부하'!A5 | B7: ='② 팀원별 부하'!G5 | C7: ='② 팀원별 부하'!H5 | D7: ='② 팀원별 부하'!I5 | E7: =IF(C7>=$B$3,"✅ 가능","❌ 어려움") | F7: =IFERROR(('② 팀원별 부하'!E5+$B$3)/'② 팀원별 부하'!D5,0)
A8: ='② 팀원별 부하'!A6 | B8: ='② 팀원별 부하'!G6 | C8: ='② 팀원별 부하'!H6 | D8: ='② 팀원별 부하'!I6 | E8: =IF(C8>=$B$3,"✅ 가능","❌ 어려움") | F8: =IFERROR(('② 팀원별 부하'!E6+$B$3)/'② 팀원별 부하'!D6,0)
A9: ='② 팀원별 부하'!A7 | B9: ='② 팀원별 부하'!G7 | C9: ='② 팀원별 부하'!H7 | D9: ='② 팀원별 부하'!I7 | E9: =IF(C9>=$B$3,"✅ 가능","❌ 어려움") | F9: =IFERROR(('② 팀원별 부하'!E7+$B$3)/'② 팀원별 부하'!D7,0)
A10: ='② 팀원별 부하'!A8 | B10: ='② 팀원별 부하'!G8 | C10: ='② 팀원별 부하'!H8 | D10: ='② 팀원별 부하'!I8 | E10: =IF(C10>=$B$3,"✅ 가능","❌ 어려움") | F10: =IFERROR(('② 팀원별 부하'!E8+$B$3)/'② 팀원별 부하'!D8,0)
A12: 💡 활용 팁
A13: • 역량 매칭: 먼저 '① 업무마스터'의 '필요 역량/스킬'·'백업담당'을 보고 후보를 좁히세요.
A14: • 대체 난이도가 '높음(전담 필수)'인 업무는 긴급 이관이 어렵습니다 — 백업담당 사전 양성이 핵심.
A15: • '여유 후 부하율'이 100%를 넘으면(빨강) 그 사람도 과부하가 되므로 분할 배정을 검토하세요.
A16: • 반복적으로 과부하가 잡히면 '자동화 가능' 업무부터 줄여 구조적으로 여력을 확보하세요.

Sheet 빈 템플릿
A1: 업무 마스터 · R&R 정의표 (빈 템플릿 — 우리 팀 내용으로 채우세요)
A2: 입력 가이드 | ① 회당 소요시간 + 주기만 넣으면 '월 환산 시간'이 자동 계산됩니다. ② '수시' 업무는 '월 발생횟수(직접)' 칸에 한 달 평균 횟수를 직접 입력하세요. ③ 주담당/백업담당/분류 등은 셀 클릭 시 드롭다운에서 선택.
A3: No | B3: 업무명 | C3: 업무분류 | D3: 업무 설명 | E3: 주담당 | F3: 백업담당 | G3: 주기 | H3: 회당 소요시간(h) | I3: 월 발생횟수 (직접·수시용) | J3: 월 환산 시간(h) | K3: 필요 역량/스킬 | L3: 대체 난이도 | M3: 자동화 가능성 | N3: 우선 순위 | O3: 비고
A4: =IF($B4="","",ROW()-3) | J4: =IF($B4="","",$H4*IF($I4<>"",$I4,IFERROR(VLOOKUP($G4,주기표,2,FALSE),0)))
A5: =IF($B5="","",ROW()-3) | J5: =IF($B5="","",$H5*IF($I5<>"",$I5,IFERROR(VLOOKUP($G5,주기표,2,FALSE),0)))
A6: =IF($B6="","",ROW()-3) | J6: =IF($B6="","",$H6*IF($I6<>"",$I6,IFERROR(VLOOKUP($G6,주기표,2,FALSE),0)))
A7: =IF($B7="","",ROW()-3) | J7: =IF($B7="","",$H7*IF($I7<>"",$I7,IFERROR(VLOOKUP($G7,주기표,2,FALSE),0)))
A8: =IF($B8="","",ROW()-3) | J8: =IF($B8="","",$H8*IF($I8<>"",$I8,IFERROR(VLOOKUP($G8,주기표,2,FALSE),0)))
A9: =IF($B9="","",ROW()-3) | J9: =IF($B9="","",$H9*IF($I9<>"",$I9,IFERROR(VLOOKUP($G9,주기표,2,FALSE),0)))
A10: =IF($B10="","",ROW()-3) | J10: =IF($B10="","",$H10*IF($I10<>"",$I10,IFERROR(VLOOKUP($G10,주기표,2,FALSE),0)))
A11: =IF($B11="","",ROW()-3) | J11: =IF($B11="","",$H11*IF($I11<>"",$I11,IFERROR(VLOOKUP($G11,주기표,2,FALSE),0)))
A12: =IF($B12="","",ROW()-3) | J12: =IF($B12="","",$H12*IF($I12<>"",$I12,IFERROR(VLOOKUP($G12,주기표,2,FALSE),0)))
A13: =IF($B13="","",ROW()-3) | J13: =IF($B13="","",$H13*IF($I13<>"",$I13,IFERROR(VLOOKUP($G13,주기표,2,FALSE),0)))
A14: =IF($B14="","",ROW()-3) | J14: =IF($B14="","",$H14*IF($I14<>"",$I14,IFERROR(VLOOKUP($G14,주기표,2,FALSE),0)))
A15: =IF($B15="","",ROW()-3) | J15: =IF($B15="","",$H15*IF($I15<>"",$I15,IFERROR(VLOOKUP($G15,주기표,2,FALSE),0)))
... A33: =IF($B33="","",ROW()-3) | J33: =IF($B33="","",$H33*IF($I33<>"",$I33,IFERROR(VLOOKUP($G33,주기표,2,FALSE),0)))
B34: 합계 / 월 총 투입시간 | J34: =SUM(J4:J33)

Sheet 참조
A1: 주기 | B1: 월 발생횟수 | D1: 업무분류 | E1: 대체난이도 | F1: 자동화 | G1: 우선순위 | H1: 팀원 | I1: 주기리스트
A2: 매일 | B2: 21 | D2: 기획 | E2: 낮음(누구나 가능) | F2: 가능 | G2: 상 | H2: 김지원(팀장/PM) | I2: 매일
A3: 주3회 | B3: 13 | D3: 운영 | E3: 중간(인수인계 필요) | F3: 일부 가능 | G3: 중 | H3: 이서연(서비스기획) | I3: 주3회
A4: 주2회 | B4: 8.67 | D4: 데이터/지표 | E4: 높음(전담 필수) | F4: 불가 | G4: 하 | H4: 박민준(운영매니저) | I4: 주2회
A5: 주간(주1회) | B5: 4.33 | D5: 유관협업 | H5: 최유나(데이터/지표) | I5: 주간(주1회)
A6: 격주 | B6: 2.17 | D6: QA/품질 | H6: 정현우(QA/지원) | I6: 격주
A7: 월간 | B7: 1 | D7: 관리/지원 | I7: 월간
A8: 분기 | B8: 0.33 | I8: 분기
A9: 반기 | B9: 0.17 | I9: 반기
A10: 연간 | B10: 0.083 | I10: 연간
A11: 수시 | B11: 0 | I11: 수시
